Workbook

Sheet Inputs
A1: Task 2 v2 · Wheel layout calculator · INPUTS
A2: Frame of [A-00] Main AMR Assembly: origin = robot centre (X = 0, Z = 0), X = width, Y = up, Z = length, mm. Y = 0 is the underside of the 1 mm Ground part, so the floor surface is Y = 1.0. Edit only BLUE values.
A4: Parameter | B4: Value | C4: Unit | D4: Source / note
A5: Measured in the CAD
A6: Floor surface Y (top of Ground part) | B6: 1 | C6: mm | D6: [A-00] Main AMR Assembly, read via SolidWorks API 2026-10-20 (GitHub e98996c)
A7: Frame outer face X (each side) | B7: 262 | C7: mm | D7: [A-00] Main AMR Assembly, read via SolidWorks API 2026-10-20 (GitHub e98996c): 3030 frame 524 wide
A8: Frame outer face Z (each end) | B8: 328 | C8: mm | D8: [A-00] Main AMR Assembly, read via SolidWorks API 2026-10-20 (GitHub e98996c): 3030 frame 656 long
A9: Frame bottom Y (underside of bottom profiles) | B9: 46.35 | C9: mm | D9: [A-00] Main AMR Assembly, read via SolidWorks API 2026-10-20 (GitHub e98996c)
A10: Top of bottom profiles = underside of First Plate | B10: 76.35 | C10: mm | D10: [A-00] Main AMR Assembly, read via SolidWorks API 2026-10-20 (GitHub e98996c)
A11: Frame top Y | B11: 166.35 | C11: mm | D11: [A-00] Main AMR Assembly, read via SolidWorks API 2026-10-20 (GitHub e98996c)
A12: Lowest chassis part Y (cross joints / tee brackets) | B12: 36.35 | C12: mm | D12: [A-00] Main AMR Assembly, read via SolidWorks API 2026-10-20 (GitHub e98996c)
A13: Drive axle centre Y (as modelled) | B13: 87 | C13: mm | D13: [A-00] Main AMR Assembly, read via SolidWorks API 2026-10-20 (GitHub e98996c) ('axe' part)
A14: Drive axle radius | B14: 9.7 | C14: mm | D14: [A-00] Main AMR Assembly, read via SolidWorks API 2026-10-20 (GitHub e98996c) (19.4 mm shaft)
A15: Drive tyre mid-plane X (each side) | B15: 294.3 | C15: mm | D15: [A-00] Main AMR Assembly, read via SolidWorks API 2026-10-20 (GitHub e98996c) (tyre X 271.3..317.3)
A16: Drive tyre inner face X | B16: 271.3 | C16: mm | D16: [A-00] Main AMR Assembly, read via SolidWorks API 2026-10-20 (GitHub e98996c)
A17: Drive tyre width | B17: 46 | C17: mm | D17: [A-00] Main AMR Assembly, read via SolidWorks API 2026-10-20 (GitHub e98996c)
... A23: Top of the caster model | B23: 77.85 | C23: mm | D23: [A-00] Main AMR Assembly, read via SolidWorks API 2026-10-20 (GitHub e98996c)
A24: Design inputs
A25: Tyre deflection under load | B25: 1 | C25: mm | D25: Solid tyre, estimate.
A26: Suspension: wheel drop needed below the floor plane | B26: 5 | C26: mm | D26: Floor dips.
A27: Minimum axle-to-profile clearance at full drop | B27: 1 | C27: mm
A28: Robot mass, empty | B28: ='Mass budget'!C16 -> 36.81128 | C28: kg | D28: Linked to the Mass budget sheet (CAD has no materials yet).
A29: Design payload | B29: 100 | C29: kg | D29: GP1 sizing basis.
A30: CG height above floor, loaded + lift raised | B30: 0.5 | C30: m | D30: Conservative.
A31: CG height above floor, empty | B31: 0.15 | C31: m | D31: Estimate.
A32: Payload CG offset from centre | B32: 0.05 | C32: m
A33: Target acceleration, loaded | B33: 0.5 | C33: m/s2
A34: Slope / ramp | B34: 2 | C34: deg
A35: Rolling resistance | B35: 0.015 | C35: -
A36: Friction, nominal | B36: 0.5 | C36: -
A37: Friction, worst | B37: 0.4 | C37: -
A38: Gravity | B38: 9.81 | C38: m/s2
A39: Spring force pressing EACH drive wheel on the floor | B39: 120 | C39: N | D39: Keep 2 x preload below ~70% of the empty weight.
A40: Vertical variation to absorb, +/- | B40: 5 | C40: mm
A41: Allowed +/- force change over that travel | B41: 0.25 | C41: -
A42: Suspension lever ratio (spring travel / wheel travel) | B42: 1 | C42: - | D42: 1 for a vertical slide.
A43: Selected caster: total height (datasheet) | B43: 64 | C43: mm | D43: Example: Revvo 50 mm low-profile, 64 mm, 160 kg (RS 750834).
A44: Selected caster: rating per caster | B44: 160 | C44: kg

Sheet Mass budget
A1: Mass budget, empty robot (estimates: the CAD parts have no material assigned yet)
A3: Item | B3: Qty | C3: Mass total (kg) | D3: Unit mass (kg) | E3: Source / note
A4: 3030 aluminium profile, total 6.67 m (cut list) | B4: 6.672 | C4: =B4*D4 -> 6.0048 | D4: 0.9 | E4: ~0.9 kg/m typical for 3030; length from 'List of components.xlsx'.
A5: Brackets, corner joints, cross joints, T-nuts, screws | B5: 1 | C5: =B5*D5 -> 1.2 | D5: 1.2 | E5: Estimate.
A6: First Plate, aluminium 460 x 580 x 3 mm | B6: 1 | C6: =B6*D6 -> 2.16 | D6: 2.16 | E6: 0.8 m2·mm x 2.7 g/cm3.
A7: Hoverboard hub motor 6.5 in with tyre | B7: 2 | C7: =B7*D7 -> 6.2 | D7: 3.1 | E7: Parallax 6.5 in hub motor listing.
A8: 2 in swivel caster | B8: 4 | C8: =B8*D8 -> 1.4 | D8: 0.35 | E8: Estimate.
A9: Drive suspension module (bracket, slide, spring) | B9: 2 | C9: =B9*D9 -> 2 | D9: 1 | E9: Estimate.
A10: Lifting mechanism (Task 3) | B10: 1 | C10: =B10*D10 -> 5 | D10: 5 | E10: Estimate; replace with Task 3 mass.
A11: Battery 36 V ~10 Ah | B11: 1 | C11: =B11*D11 -> 3 | D11: 3 | E11: Estimate.
A12: Electronics | B12: 1 | C12: =B12*D12 -> 2.5 | D12: 2.5 | E12: Estimate.
A13: Cover, 3 mm sheet (Task 4) | B13: 1 | C13: =B13*D13 -> 4 | D13: 4 | E13: Estimate; Task 4 uses 3 mm sheet.
A14: Subtotal | C14: =SUM(C4:C13) -> 33.4648
A15: Design margin (10%) | C15: =0.1*C14 -> 3.34648
A16: Empty robot mass used in calculations | C16: =C14+C15 -> 36.81128

Sheet Results
A1: Task 2 v2 · RESULTS (formulas, do not edit)
A3: Result | B3: Value | C3: Unit | D3: Meaning / check
A4: 1. Vertical alignment (as modelled)
A5: Drive tyre bottom Y (axle Y - tyre D/2) | B5: =Inputs!$B$13-Inputs!$B$18/2 -> 1 | C5: mm | D5: Should equal the floor Y
A6: Drive tyre vs floor | B6: =$B$5-Inputs!$B$6 -> 0 | C6: mm | D6: 0 = drive wheels and casters on the same plane
A7: Floor to caster mounting face (underside of First Plate) | B7: =Inputs!$B$10-Inputs!$B$6 -> 75.35 | C7: mm
A8: Caster model top above the mounting face | B8: =Inputs!$B$23-Inputs!$B$10 -> 1.5 | C8: mm | D8: >0 = the caster model pokes into the plate
A9: Ground clearance under the frame | B9: =Inputs!$B$9-Inputs!$B$6 -> 45.35 | C9: mm
A10: Ground clearance under the lowest chassis part | B10: =Inputs!$B$12-Inputs!$B$6 -> 35.35 | C10: mm
A11: Tyre top above the frame top | B11: =Inputs!$B$13+Inputs!$B$18/2-Inputs!$B$11 -> 6.65 | C11: mm | D11: >0 = needs wheel wells in the cover
A12: Gap tyre inner face to frame outer face | B12: =Inputs!$B$16-Inputs!$B$7 -> 9.3 | C12: mm
A13: 2. Axle clearance over the bottom side profile (the axle passes over it at Z = 0)
A14: Gap as modelled (axle unloaded) | B14: =Inputs!$B$13-Inputs!$B$14-Inputs!$B$10 -> 0.95 | C14: mm
A15: Gap under load (tyre compressed) | B15: =Inputs!$B$6+Inputs!$B$18/2-Inputs!$B$25-Inputs!$B$14-Inputs!$B$10 -> -0.05 | C15: mm | D15: <0 = the axle sits on the profile
A16: Gap needed (droop + clearance) | B16: =Inputs!$B$26+Inputs!$B$27 -> 6 | C16: mm
A17: Lower the frame by (whole mm) | B17: =MAX(0,ROUNDUP($B$16-$B$15,0)) -> 7 | C17: mm | D17: By shortening the installed casters
A18: New floor-to-caster-face height | B18: =$B$7-$B$17 -> 68.35 | C18: mm | D18: Caster + spacer must equal this
A19: Spacer for the selected caster | B19: =$B$18-Inputs!$B$43 -> 4.35 | C19: mm
A20: Selected caster fits? | B20: =IF($B$19<0,"NO: too tall","OK") -> OK
A21: New clearance under the lowest part | B21: =$B$10-$B$17 -> 28.35 | C21: mm
A22: New tyre top above the frame top | B22: =$B$11+$B$17 -> 13.65 | C22: mm
A23: 3. Plan geometry
A24: Track (tyre mid-planes) | B24: =2*Inputs!$B$15 -> 588.6 | C24: mm
A25: Width over the tyres | B25: =2*(Inputs!$B$16+Inputs!$B$17) -> 634.6 | C25: mm
A26: Caster track (X) | B26: =2*Inputs!$B$19 -> 350 | C26: mm
A27: Caster wheelbase (Z) | B27: =2*Inputs!$B$20 -> 461.6 | C27: mm
A28: Caster swivel envelope radius | B28: =Inputs!$B$22+Inputs!$B$21/2 -> 48.35 | C28: mm
A29: In-place rotation radius (frame corners) | B29: =SQRT(Inputs!$B$7^2+Inputs!$B$8^2) -> 419.79519 | C29: mm | D29: Add the cover thickness
A30: 4. Stability (casters swivelled inwards)
A31: Caster inner contact X | B31: =Inputs!$B$19-Inputs!$B$22 -> 152 | C31: mm
A32: Caster inner contact Z | B32: =Inputs!$B$20-Inputs!$B$22 -> 207.8 | C32: mm
A33: Margin to the caster-to-drive-wheel edge | B33: =ABS(Inputs!$B$15*$B$32)/SQRT((Inputs!$B$15-$B$31)^2+$B$32^2)/1000 -> 0.24282198 | C33: m
A34: Margin to the end edge | B34: =$B$32/1000 -> 0.2078 | C34: m
A35: Smallest margin | B35: =MIN($B$33,$B$34) -> 0.2078 | C35: m
A36: Tip-over acceleration limit, loaded | B36: =Inputs!$B$38*($B$35-Inputs!$B$32)/Inputs!$B$30 -> 3.096036 | C36: m/s2
A37: Tip-over acceleration limit, empty | B37: =Inputs!$B$38*$B$35/Inputs!$B$31 -> 13.59012 | C37: m/s2
A38: 5. Drive, traction and casters
A39: Loaded mass | B39: =Inputs!$B$28+Inputs!$B$29 -> 136.81128 | C39: kg
A40: Loaded wheel radius | B40: =(Inputs!$B$18/2-Inputs!$B$25)/1000 -> 0.085 | C40: m
A41: Drive force, loaded, slope, target acceleration | B41: =$B$39*(Inputs!$B$38*Inputs!$B$35*COS(RADIANS(Inputs!$B$34))+Inputs!$B$38*SIN(RADIANS(Inputs!$B$34))+Inputs!$B$33) -> 135.36442 | C41: N
...
